[32mINFO    [0m integration.test_exporter:test_exporter.py:202 Deploying self-signed-certificates
[32mINFO    [0m juju.model:model.py:2069 Deploying ch:amd64/jammy/self-signed-certificates-72
[32mINFO    [0m juju.model:model.py:2759 Waiting for model:
  self-signed-certificates/0 [allocating] waiting: installing agent
[32mINFO    [0m integration.test_exporter:test_exporter.py:213 Relating mysqlrouter with self-signed-certificates
[33mWARNING [0m juju.model:model.py:1558 relate is deprecated and will be removed. Use integrate instead.
[33mWARNING [0m urllib3.connectionpool:connectionpool.py:823 Retrying (Retry(total=2, connect=None, read=None, redirect=None, status=None)) after connection broken by 'NewConnectionError('<urllib3.connection.HTTPConnection object at 0x7fba31eef8e0>: Failed to establish a new connection: [Errno 111] Connection refused')': /metrics
[33mWARNING [0m urllib3.connectionpool:connectionpool.py:823 Retrying (Retry(total=1, connect=None, read=None, redirect=None, status=None)) after connection broken by 'NewConnectionError('<urllib3.connection.HTTPConnection object at 0x7fba31eec130>: Failed to establish a new connection: [Errno 111] Connection refused')': /metrics
[33mWARNING [0m urllib3.connectionpool:connectionpool.py:823 Retrying (Retry(total=0, connect=None, read=None, redirect=None, status=None)) after connection broken by 'NewConnectionError('<urllib3.connection.HTTPConnection object at 0x7fba31eec1c0>: Failed to establish a new connection: [Errno 111] Connection refused')': /metrics
[32mINFO    [0m integration.test_exporter:test_exporter.py:239 Relating mysqlrouter with grafana agent
[33mWARNING [0m juju.model:model.py:1558 relate is deprecated and will be removed. Use integrate instead.
[33mWARNING [0m urllib3.connectionpool:connectionpool.py:823 Retrying (Retry(total=2, connect=None, read=None, redirect=None, status=None)) after connection broken by 'NewConnectionError('<urllib3.connection.HTTPConnection object at 0x7fba31a0bf40>: Failed to establish a new connection: [Errno 111] Connection refused')': /metrics
[33mWARNING [0m urllib3.connectionpool:connectionpool.py:823 Retrying (Retry(total=1, connect=None, read=None, redirect=None, status=None)) after connection broken by 'NewConnectionError('<urllib3.connection.HTTPConnection object at 0x7fba31de2cb0>: Failed to establish a new connection: [Errno 111] Connection refused')': /metrics
[33mWARNING [0m urllib3.connectionpool:connectionpool.py:823 Retrying (Retry(total=0, connect=None, read=None, redirect=None, status=None)) after connection broken by 'NewConnectionError('<urllib3.connection.HTTPConnection object at 0x7fba31de1db0>: Failed to establish a new connection: [Errno 111] Connection refused')': /metrics
[32mINFO    [0m integration.test_exporter:test_exporter.py:266 Removing relation between mysqlrouter and grafana agent
[33mWARNING [0m urllib3.connectionpool:connectionpool.py:823 Retrying (Retry(total=2, connect=None, read=None, redirect=None, status=None)) after connection broken by 'NewConnectionError('<urllib3.connection.HTTPConnection object at 0x7fba31de3d30>: Failed to establish a new connection: [Errno 111] Connection refused')': /metrics
[33mWARNING [0m urllib3.connectionpool:connectionpool.py:823 Retrying (Retry(total=1, connect=None, read=None, redirect=None, status=None)) after connection broken by 'NewConnectionError('<urllib3.connection.HTTPConnection object at 0x7fba31c80a30>: Failed to establish a new connection: [Errno 111] Connection refused')': /metrics
[33mWARNING [0m urllib3.connectionpool:connectionpool.py:823 Retrying (Retry(total=0, connect=None, read=None, redirect=None, status=None)) after connection broken by 'NewConnectionError('<urllib3.connection.HTTPConnection object at 0x7fba31c82b90>: Failed to establish a new connection: [Errno 111] Connection refused')': /metrics
[32mINFO    [0m integration.test_exporter:test_exporter.py:286 Removing relation between mysqlrouter and self-signed-certificates
[32mINFO    [0m pytest_operator.plugin:plugin.py:790 Model status:

Model  Controller          Cloud/Region        Version  SLA          Timestamp
test   microk8s-localhost  microk8s/localhost  3.4.3    unsupported  01:39:36Z

App                       Version                  Status   Scale  Charm                     Channel        Rev  Address         Exposed  Message
grafana-agent-k8s         0.35.2                   waiting      1  grafana-agent-k8s         latest/stable   68  10.152.183.24   no       installing agent
mysql-k8s                 8.0.36-0ubuntu0.22.04.1  active       1  mysql-k8s                 8.0/edge       150  10.152.183.103  no       
mysql-router-k8s          8.0.36-0ubuntu0.22.04.1  active       1  mysql-router-k8s                           0  10.152.183.225  no       
mysql-test-app            0.0.2                    active       1  mysql-test-app            latest/edge     38  10.152.183.58   no       Last written value=725
self-signed-certificates                           active       1  self-signed-certificates  latest/stable   72  10.152.183.78   no       

Unit                         Workload  Agent  Address      Ports  Message
grafana-agent-k8s/0*         blocked   idle   10.1.57.201         Missing ['grafana-cloud-config']|['grafana-dashboards-provider'] for grafana-dashboards-consumer; ['grafana-cloud-con...
mysql-k8s/0*                 active    idle   10.1.57.205         Primary
mysql-router-k8s/0*          active    idle   10.1.57.203         
mysql-test-app/0*            active    idle   10.1.57.202         Last written value=725
self-signed-certificates/0*  active    idle   10.1.57.206         

[32mINFO    [0m pytest_operator.plugin:plugin.py:796 Juju error logs:


[32mINFO    [0m pytest_operator.plugin:plugin.py:862 Forgetting main...
[31m[1mERROR   [0m websockets.client:protocol.py:1015 data transfer failed
Traceback (most recent call last):
  File "/home/runner/work/mysql-router-k8s-operator/mysql-router-k8s-operator/.tox/integration/lib/python3.10/site-packages/websockets/legacy/protocol.py", line 959, in transfer_data
    message = await self.read_message()
  File "/home/runner/work/mysql-router-k8s-operator/mysql-router-k8s-operator/.tox/integration/lib/python3.10/site-packages/websockets/legacy/protocol.py", line 1029, in read_message
    frame = await self.read_data_frame(max_size=self.max_size)
  File "/home/runner/work/mysql-router-k8s-operator/mysql-router-k8s-operator/.tox/integration/lib/python3.10/site-packages/websockets/legacy/protocol.py", line 1104, in read_data_frame
    frame = await self.read_frame(max_size)
  File "/home/runner/work/mysql-router-k8s-operator/mysql-router-k8s-operator/.tox/integration/lib/python3.10/site-packages/websockets/legacy/protocol.py", line 1161, in read_frame
    frame = await Frame.read(
  File "/home/runner/work/mysql-router-k8s-operator/mysql-router-k8s-operator/.tox/integration/lib/python3.10/site-packages/websockets/legacy/framing.py", line 68, in read
    data = await reader(2)
  File "/usr/lib/python3.10/asyncio/streams.py", line 708, in readexactly
    await self._wait_for_data('readexactly')
  File "/usr/lib/python3.10/asyncio/streams.py", line 501, in _wait_for_data
    await self._waiter
  File "/usr/lib/python3.10/asyncio/selector_events.py", line 924, in write
    n = self._sock.send(data)
OSError: [Errno 9] Bad file descriptor