[32mINFO    [0m pytest_operator.plugin:plugin.py:734 Connecting to existing model microk8s-localhost:test on unspecified cloud
[32mINFO    [0m integration.test_exporter_with_tls:test_exporter_with_tls.py:63 Deploying all the applications
[32mINFO    [0m juju.model:model.py:2097 Deploying local:jammy/mysql-router-k8s-0
[32mINFO    [0m juju.model:model.py:2097 Deploying ch:amd64/jammy/mysql-test-app-46
[32mINFO    [0m juju.model:model.py:2097 Deploying ch:amd64/jammy/grafana-agent-k8s-45
[32mINFO    [0m juju.model:model.py:2097 Deploying ch:amd64/jammy/mysql-k8s-169
[32mINFO    [0m integration.test_exporter_with_tls:test_exporter_with_tls.py:100 Waiting for mysqlrouter to be in BlockedStatus
[32mINFO    [0m pytest_operator.plugin:plugin.py:862 Model status:

Model  Controller          Cloud/Region        Version  SLA          Timestamp
test   microk8s-localhost  microk8s/localhost  3.4.3    unsupported  02:16:09Z

App                Version                  Status   Scale  Charm              Channel        Rev  Address         Exposed  Message
grafana-agent-k8s  0.32.1                   waiting      1  grafana-agent-k8s  latest/stable   45  10.152.183.131  no       installing agent
mysql-k8s          8.0.37-0ubuntu0.22.04.3  active       1  mysql-k8s          8.0/edge       169  10.152.183.97   no       
mysql-router-k8s                            waiting      1  mysql-router-k8s                    0  10.152.183.69   no       installing agent
mysql-test-app     0.0.2                    waiting      1  mysql-test-app     latest/edge     46  10.152.183.41   no       installing agent

Unit                  Workload  Agent  Address    Ports  Message
grafana-agent-k8s/0*  blocked   idle   10.1.5.12         Missing incoming ('requires') relation
mysql-k8s/0*          active    idle   10.1.5.13         Primary
mysql-router-k8s/0*   unknown   idle   10.1.5.8          
mysql-test-app/0*     waiting   idle   10.1.5.9          

[32mINFO    [0m pytest_operator.plugin:plugin.py:868 Juju error logs:

unit-mysql-k8s-0: 01:51:59 ERROR unit.mysql-k8s/0.juju-log upgrade:7: Uncaught exception while in charm code:
Traceback (most recent call last):
  File "/var/lib/juju/agents/unit-mysql-k8s-0/charm/./src/charm.py", line 866, in <module>
    main(MySQLOperatorCharm)
  File "/var/lib/juju/agents/unit-mysql-k8s-0/charm/venv/ops/main.py", line 551, in main
    manager.run()
  File "/var/lib/juju/agents/unit-mysql-k8s-0/charm/venv/ops/main.py", line 530, in run
    self._emit()
  File "/var/lib/juju/agents/unit-mysql-k8s-0/charm/venv/ops/main.py", line 519, in _emit
    _emit_charm_event(self.charm, self.dispatcher.event_name)
  File "/var/lib/juju/agents/unit-mysql-k8s-0/charm/venv/ops/main.py", line 147, in _emit_charm_event
    event_to_emit.emit(*args, **kwargs)
  File "/var/lib/juju/agents/unit-mysql-k8s-0/charm/venv/ops/framework.py", line 348, in emit
    framework._emit(event)
  File "/var/lib/juju/agents/unit-mysql-k8s-0/charm/venv/ops/framework.py", line 860, in _emit
    self._reemit(event_path)
  File "/var/lib/juju/agents/unit-mysql-k8s-0/charm/venv/ops/framework.py", line 950, in _reemit
    custom_handler(event)
  File "/var/lib/juju/agents/unit-mysql-k8s-0/charm/lib/charms/tempo_k8s/v1/charm_tracing.py", line 647, in wrapped_function
    return callable(*args, **kwargs)  # type: ignore
  File "/var/lib/juju/agents/unit-mysql-k8s-0/charm/src/upgrade.py", line 205, in _on_upgrade_changed
    if not self.upgrade_stack and self.idle and self.charm.unit_initialized:
  File "/var/lib/juju/agents/unit-mysql-k8s-0/charm/lib/charms/mysql/v0/mysql.py", line 634, in unit_initialized
    return self._mysql.cluster_metadata_exists(self.get_unit_address(self.unit))
  File "/var/lib/juju/agents/unit-mysql-k8s-0/charm/lib/charms/tempo_k8s/v1/charm_tracing.py", line 647, in wrapped_function
    return callable(*args, **kwargs)  # type: ignore
  File "/var/lib/juju/agents/unit-mysql-k8s-0/charm/lib/charms/mysql/v0/mysql.py", line 1412, in cluster_metadata_exists
    output = self._run_mysqlsh_script("\n".join(check_cluster_metadata_commands))
  File "/var/lib/juju/agents/unit-mysql-k8s-0/charm/lib/charms/tempo_k8s/v1/charm_tracing.py", line 647, in wrapped_function
    return callable(*args, **kwargs)  # type: ignore
  File "/var/lib/juju/agents/unit-mysql-k8s-0/charm/src/mysql_k8s_helpers.py", line 594, in _run_mysqlsh_script
    self.container.push(path=MYSQLSH_SCRIPT_FILE, source=script)
  File "/var/lib/juju/agents/unit-mysql-k8s-0/charm/venv/ops/model.py", line 2438, in push
    self._pebble.push(
  File "/var/lib/juju/agents/unit-mysql-k8s-0/charm/venv/ops/pebble.py", line 2494, in push
    response = self._request_raw('POST', '/v1/files', None, headers, data)
  File "/var/lib/juju/agents/unit-mysql-k8s-0/charm/venv/ops/pebble.py", line 2048, in _request_raw
    raise ConnectionError(
ops.pebble.ConnectionError: Could not connect to Pebble: socket not found at '/charm/containers/mysql/pebble.socket' (container restarted?)
unit-mysql-k8s-0: 01:52:00 ERROR juju.worker.uniter.operation hook "upgrade-relation-changed" (via hook dispatching script: dispatch) failed: exit status 1

[32mINFO    [0m pytest_operator.plugin:plugin.py:947 Forgetting model main...