{"uid":"4b4757e66a1912dae1a509f688f20b0f","children":[{"name":"Test defects","children":[{"name":"urllib3.exceptions.MaxRetryError: HTTPConnectionPool(host='10.1.110.76', port=49152): Max retries exceeded with url: /metrics (Caused by NewConnectionError('<urllib3.connection.HTTPConnection object at 0x7fa271ac6ec0>: Failed to establish a new connection: [Errno 111] Connection refused'))","children":[{"name":"test_exporter_endpoint","uid":"885ca108b9656944","parentUid":"0f8149269d767bcf41dc5ce0bbd06fbc","status":"broken","time":{"start":1719106571950,"stop":1719106877684,"duration":305734},"flaky":false,"newFailed":false,"newPassed":false,"newBroken":true,"retriesCount":1,"retriesStatusChange":true,"parameters":[],"tags":["asyncio","abort_on_fail","group(1)"]}],"uid":"0f8149269d767bcf41dc5ce0bbd06fbc"}],"uid":"bdbf199525818fae7a8651db9eafe741"}],"name":"categories"}