[32mINFO    [0m pytest_operator.plugin:plugin.py:675 Connecting to existing model microk8s-localhost:test on unspecified cloud
[33mWARNING [0m juju.client.connection:connection.py:927 unexpected facade UserSecretsDrain received from the controller
[33mWARNING [0m juju.client.connection:connection.py:927 unexpected facade UserSecretsManager received from the controller
[32mINFO    [0m integration.test_exporter:test_exporter.py:55 Deploying all the applications
[32mINFO    [0m juju.model:model.py:2069 Deploying ch:amd64/jammy/mysql-test-app-38
[32mINFO    [0m juju.model:model.py:2069 Deploying ch:amd64/jammy/mysql-k8s-152
[32mINFO    [0m juju.model:model.py:2069 Deploying ch:amd64/jammy/grafana-agent-k8s-45
[32mINFO    [0m juju.model:model.py:2069 Deploying local:jammy/mysql-router-k8s-0
[32mINFO    [0m integration.test_exporter:test_exporter.py:94 Waiting for mysqlrouter to be in BlockedStatus
[32mINFO    [0m integration.test_exporter:test_exporter.py:100 Relating mysql, mysqlrouter and application
[33mWARNING [0m juju.model:model.py:1558 relate is deprecated and will be removed. Use integrate instead.
[33mWARNING [0m juju.model:model.py:1558 relate is deprecated and will be removed. Use integrate instead.
[32mINFO    [0m juju.model:model.py:2759 Waiting for model:
  mysql-router-k8s/0 [executing] maintenance: Waiting for container
[32mINFO    [0m juju.model:model.py:2759 Waiting for model:
  mysql-router-k8s/0 [idle] waiting: 
[32mINFO    [0m juju.model:model.py:2759 Waiting for model:
  mysql-router-k8s/0 [idle] active: 
[32mINFO    [0m juju.model:model.py:2759 Waiting for model:
  mysql-k8s/0 [idle] active: Primary
  mysql-router-k8s/0 [idle] active: 
  mysql-test-app/0 [idle] active: 
[33mWARNING [0m urllib3.connectionpool:connectionpool.py:823 Retrying (Retry(total=2, connect=None, read=None, redirect=None, status=None)) after connection broken by 'NewConnectionError('<urllib3.connection.HTTPConnection object at 0x7f81900fe080>: Failed to establish a new connection: [Errno 111] Connection refused')': /metrics
[33mWARNING [0m urllib3.connectionpool:connectionpool.py:823 Retrying (Retry(total=1, connect=None, read=None, redirect=None, status=None)) after connection broken by 'NewConnectionError('<urllib3.connection.HTTPConnection object at 0x7f818f6d4b20>: Failed to establish a new connection: [Errno 111] Connection refused')': /metrics
[33mWARNING [0m urllib3.connectionpool:connectionpool.py:823 Retrying (Retry(total=0, connect=None, read=None, redirect=None, status=None)) after connection broken by 'NewConnectionError('<urllib3.connection.HTTPConnection object at 0x7f818f6d5a50>: Failed to establish a new connection: [Errno 111] Connection refused')': /metrics
[32mINFO    [0m integration.test_exporter:test_exporter.py:134 Relating mysqlrouter with grafana agent
[33mWARNING [0m juju.model:model.py:1558 relate is deprecated and will be removed. Use integrate instead.
[33mWARNING [0m juju.model:model.py:1558 relate is deprecated and will be removed. Use integrate instead.
[33mWARNING [0m juju.model:model.py:1558 relate is deprecated and will be removed. Use integrate instead.
[33mWARNING [0m urllib3.connectionpool:connectionpool.py:823 Retrying (Retry(total=2, connect=None, read=None, redirect=None, status=None)) after connection broken by 'NewConnectionError('<urllib3.connection.HTTPConnection object at 0x7f818f6d4a00>: Failed to establish a new connection: [Errno 111] Connection refused')': /metrics
[33mWARNING [0m urllib3.connectionpool:connectionpool.py:823 Retrying (Retry(total=1, connect=None, read=None, redirect=None, status=None)) after connection broken by 'NewConnectionError('<urllib3.connection.HTTPConnection object at 0x7f81900fedd0>: Failed to establish a new connection: [Errno 111] Connection refused')': /metrics
[33mWARNING [0m urllib3.connectionpool:connectionpool.py:823 Retrying (Retry(total=0, connect=None, read=None, redirect=None, status=None)) after connection broken by 'NewConnectionError('<urllib3.connection.HTTPConnection object at 0x7f81900fe7a0>: Failed to establish a new connection: [Errno 111] Connection refused')': /metrics
[32mINFO    [0m integration.test_exporter:test_exporter.py:160 Removing relation between mysqlrouter and grafana agent
[33mWARNING [0m urllib3.connectionpool:connectionpool.py:823 Retrying (Retry(total=2, connect=None, read=None, redirect=None, status=None)) after connection broken by 'NewConnectionError('<urllib3.connection.HTTPConnection object at 0x7f818fac8f10>: Failed to establish a new connection: [Errno 111] Connection refused')': /metrics
[33mWARNING [0m urllib3.connectionpool:connectionpool.py:823 Retrying (Retry(total=1, connect=None, read=None, redirect=None, status=None)) after connection broken by 'NewConnectionError('<urllib3.connection.HTTPConnection object at 0x7f818fac8400>: Failed to establish a new connection: [Errno 111] Connection refused')': /metrics
[33mWARNING [0m urllib3.connectionpool:connectionpool.py:823 Retrying (Retry(total=0, connect=None, read=None, redirect=None, status=None)) after connection broken by 'NewConnectionError('<urllib3.connection.HTTPConnection object at 0x7f818fac9240>: Failed to establish a new connection: [Errno 111] Connection refused')': /metrics